Workbook

Sheet RuleSets
A3: SNORT (v2.9) | N3: RuleSets Omitidos
N4: Talos Community SIN interés
A5: Paquete de Reglas | B5: Descripción | C5: Fichero | D5: Nº de Reglas | E5: Versión | F5: Fecha | G5: RS1 | H5: RS2 | I5: RS3 | J5: RS4 | K5: RS5 | L5: RS6 | N5: RS7 | O5: RS8 | P5: RS9 | R5: RS10 ≈ RS3 (RS7 sólo aporta 1 SID) | S5: RS11 = RS6 | T5: RS12 = RS6
A6: Talos Registered (por defecto) | B6: Reglas supervisadas por el grupo Talos, tal como se descargan para Snort v2.9 (sin modificar configuración ni reglas comentadas) Fusión de todos los ficheros ".rules" del paquete (preproc_rules, rules y so_rules) que tienen el "include" SIN comentar | C6: registered-all.rules | D6: 15684 | F6: 46113 | G6: ✔ | I6: ✔ | P6: ✔ | R6: ✔ | U6: https://www.snort.org/downloads Community: community-rules.tar.gz Registered: snortrules-snapshot-xxx.tar.gz
A7: ETOpen (por defecto) | B7: Reglas "Emerging Threats", tal como se descargan (sin modificar configuración ni reglas comentadas) | C7: emerging-all.rules | D7: 36658 | E7: 11168 | F7: 46113 | H7: ✔ | I7: ✔ | P7: ✔ | R7: ✔ | U7: https://rules.emergingthreats.net/open/snort-2.9.0/
A8: Talos Registered (máxima CD) | B8: Talos Registered, descomentando todas las reglas (#) y todos los "include" de ficheros ".rules" (salvo el fichero "deleted.rules", con "DELETED" al principio del "msg") Fusión de todos los ficheros ".rules" del paquete | C8: registered-all-descomentadas.rules | D8: 53465 | F8: 46113 | J8: ✔ | L8: ✔ | S8: ✔ | T8: ✔
A9: ETOpen (máxima CD) | B9: ETOpen, descomentando todas las reglas (salvo las reglas marcadas como "msg:"ET DELETED" o fichero "emerging-deleted.rules" - hay "12271" deleted) | C9: emerging-all-descomentadas.rules | D9: 64762 | F9: 46113 | K9: ✔ | L9: ✔ | S9: ✔ | T9: ✔
A10: Talos Community (por defecto) | B10: Reglas de la Comunidad (GPLv2), tal como se descargan (sin modificar reglas comentadas) | C10: community.rules | D10: 561 * Talos Registered por defecto: Todas salvo 1 (sid:59735) * Registered máxima CD: Todas | F10: 46113 | N10: ✔ | R10: ✔ (sólo aporta 1 SID, 59735) | S10: ✔ (contenido en RS4)
A11: Talos Community (máxima CD) | B11: Reglas de la Comunidad (GPLv2), descomentando todas las reglas | C11: community.rules | D11: 4013 * Talos Registered por defecto: No contiene 3453 (560 reglas en común, las no comentadas, salvo "sid:59735") * Registered máxima CD: Todas | F11: 46113 | O11: ✔ | P11: ✔ | T11: ✔ (contenido en RS4)
A15: FORTIGATE
A16: Nombre Reglas | B16: Descripción | C16: #Reglas IPS (Security Profiles / IPS Signatures) | D16: #Reglas Aplicación (Security Profiles / Application Signatures) | E16: IPS Definitions | F16: IPS Engine | G16: Fecha | H16: Dispositivo
A17: FortiGate | B17: Consulta de reglas IPS: https://fortiguard.fortinet.com/encyclopedia/ips/xxx | C17: 12202 | D17: 9407 | E17: Version 33.00053 | F17: Version 7.00600 | G17: 46139 | H17: FGVM02
A19: PALOALTO NGFW
A20: Nombre Reglas | B20: Descripción | C20: #Reglas IPS (OBJECTS > Security Profiles > Vulnerability Protection > ESI > Exceptions > Marcar "Show All signatures") | D20: #Reglas Aplicación (OBJECTS > Applications) | E20: IPS Definitions | F20: IPS Engine | G20: Fecha | H20: Dispositivo
A21: PaloAlto | B21: Consulta de reglas IPS: https://threatvault.paloaltonetworks.com/?query=xxxxx | C21: 22085 | D21: 5420 | E21: PAN-OS 10.2.11 | F21: PAN-OS 10.2.11 | G21: 46139 | H21: PA-VM
A23: Niveles de Prioridad/Riesgo/Severidad
A24: N (Nivel de Riesgo) | B24: Snort [Priority] | C24: FG | E24: PA
C25: IPS (severity) | D25: APP (apprisk) | E25: IPS (severity_number) | F25: APP (risk_of_app)
A26: 1 | B26: Crítica | C26: info | D26: information | E26: Informational | F26: Information | G26: ADVERTIR: Snort y FG/PA usan "N" en orden inverso (e.g. N=1 es máximo para Snort y mínimo para FG/PA)
A27: 2 | B27: Alta | C27: low | D27: low | E27: Lowal | F27: Low
A28: 3 | B28: Media | C28: medium | D28: medium | E28: Medium | F28: Medium
A29: 4 | B29: Baja | C29: high | D29: high | E29: High | F29: High
A30: 5 | B30: - | C30: critical | D30: elevated | E30: Critical | F30: Elevated

Sheet Tabla 3 (Legítimo)
B1: Snort [Priority <= 4 (Any)] | K1: FG | M1: PA
A2: Metric | B2: RS1 | C2: RS2 | D2: RS3 | E2: RS4 | F2: RS5 | G2: RS6 | H2: RS7 | I2: RS8 | J2: RS9 | K2: [IPS severity >=1 (Any)] | L2: [IPS severity >=1 (Any)] || [App apprisk >= 1 (Any)] | M2: [IPS severity >=1 (Any)] | N2: [IPS severity_number >=1 (Any)] || [App risk_of_app >= 1 (Any)]
A3: #Flows | B3: ='(B) Legitimo'!D3 -> 78694206
A4: #Alerts | B4: ='(B) Legitimo'!G3 -> 9778069 | C4: ='(B) Legitimo'!M3 -> 5500009 | D4: ='(B) Legitimo'!S3 -> 15278078 | E4: ='(B) Legitimo'!Y3 -> 15309135 | F4: ='(B) Legitimo'!AE3 -> 14539188 | G4: ='(B) Legitimo'!AK3 -> 29848323 | H4: ='(B) Legitimo'!AQ3 -> 6990 | I4: ='(B) Legitimo'!AW3 -> 8738223 | J4: ='(B) Legitimo'!BC3 -> 24009324 | K4: ='(B) Legitimo'!JZ3+'(B) Legitimo'!KF3+'(B) Legitimo'!KL3+'(B) Legitimo'!KR3+'(B) Legitimo'!KX3 -> 4445687 | L4: ='(B) Legitimo'!JQ3 -> 25983916 | M4: ='(B) Legitimo'!MH3 -> 31273 | N4: ='(B) Legitimo'!MH3 -> 31273
A5: #Flow-correlated Alerts | B5: ='(B) Legitimo'!I3 -> 8620288 | C5: ='(B) Legitimo'!O3 -> 5136879 | D5: ='(B) Legitimo'!U3 -> 13757167 | E5: ='(B) Legitimo'!AA3 -> 13128811 | F5: ='(B) Legitimo'!AG3 -> 13066562 | G5: ='(B) Legitimo'!AM3 -> 26195373 | H5: ='(B) Legitimo'!AS3 -> 6420 | I5: ='(B) Legitimo'!AY3 -> 7505544 | J5: ='(B) Legitimo'!BE3 -> 21256304 | K5: ='(B) Legitimo'!KB3+'(B) Legitimo'!KH3+'(B) Legitimo'!KN3+'(B) Legitimo'!KT3+'(B) Legitimo'!KZ3 -> 4421445 | L5: ='(B) Legitimo'!JR3 -> 25704108 | M5: ='(B) Legitimo'!MI3 -> 56932 | N5: ='(B) Legitimo'!MI3 -> 56932
A6: #SIDs, #AttackID o #ThreatID | B6: ='(B) Legitimo'!K3 -> 22 | C6: ='(B) Legitimo'!Q3 -> 71 | D6: ='(B) Legitimo'!W3 -> 93 | E6: ='(B) Legitimo'!AC3 -> 214 | F6: ='(B) Legitimo'!AI3 -> 229 | G6: ='(B) Legitimo'!AO3 -> 443 | H6: ='(B) Legitimo'!AU3 -> 2 | I6: ='(B) Legitimo'!BA3 -> 63 | J6: ='(B) Legitimo'!BG3 -> 154 | K6: ='(B) Legitimo'!KD3+'(B) Legitimo'!KV3+'(B) Legitimo'!KJ3+'(B) Legitimo'!KP3+'(B) Legitimo'!LB3 -> 30 | L6: ='(B) Legitimo'!JS3 -> 30 | M6: ='(B) Legitimo'!MJ3 -> 14 | N6: ='(B) Legitimo'!MJ3 -> 14
A7: #AppID | B7: N/A | C7: N/A | D7: N/A | E7: N/A | F7: N/A | G7: N/A | H7: N/A | I7: N/A | J7: N/A | K7: N/A | L7: ='(B) Legitimo'!JT3 -> 134 | M7: N/A | N7: ='(B) Legitimo'!MK3 -> 14
A8: #Flows_FP | B8: ='(B) Legitimo'!L3 -> 3391362 | C8: ='(B) Legitimo'!R3 -> 4719941 | D8: ='(B) Legitimo'!X3 -> 7276338 | E8: ='(B) Legitimo'!AD3 -> 6879262 | F8: ='(B) Legitimo'!AJ3 -> 6115454 | G8: ='(B) Legitimo'!AP3 -> 9478500 | H8: ='(B) Legitimo'!AV3 -> 6398 | I8: ='(B) Legitimo'!BB3 -> 7470907 | J8: ='(B) Legitimo'!BH3 -> 10855081 | K8: ='(B) Legitimo'!JV3 -> 4412536 | L8: ='(B) Legitimo'!JX3 -> 18610671 | M8: ='(B) Legitimo'!MM3 -> 28174 | N8: ='(B) Legitimo'!MO3 -> 28174
A9: #Flows_TN | B9: =$B$3-B8 -> 75302844 | C9: =$B$3-C8 -> 73974265 | D9: =$B$3-D8 -> 71417868 | E9: =$B$3-E8 -> 71814944 | F9: =$B$3-F8 -> 72578752 | G9: =$B$3-G8 -> 69215706 | H9: =$B$3-H8 -> 78687808 | I9: =$B$3-I8 -> 71223299 | ... N9: =$B$3-N8 -> 78666032
A10: %Flows_FP | B10: =B8/$B$3 -> 0.043095447 | C10: =C8/$B$3 -> 0.059978253 | D10: =D8/$B$3 -> 0.092463453 | E10: =E8/$B$3 -> 0.087417643 | F10: =F8/$B$3 -> 0.077711617 | G10: =G8/$B$3 -> 0.12044724 | H10: =H8/$B$3 -> 8.1302047e-05 | I10: =I8/$B$3 -> 0.094935922 | ... N10: =N8/$B$3 -> 0.00035801873
A11: %Flows_TN | B11: =1-B10 -> 0.95690455 | C11: =1-C10 -> 0.94002175 | D11: =1-D10 -> 0.90753655 | E11: =1-E10 -> 0.91258236 | F11: =1-F10 -> 0.92228838 | G11: =1-G10 -> 0.87955276 | H11: =1-H10 -> 0.9999187 | I11: =1-I10 -> 0.90506408 | ... N11: =1-N10 -> 0.99964198
B13: Snort [Priority <=3] | K13: FG | M13: PA
A14: Metric | B14: RS1 | C14: RS2 | D14: RS3 | E14: RS4 | F14: RS5 | G14: RS6 | H14: RS7 | I14: RS8 | J14: RS9 | K14: [IPS severity >=2] | L14: [IPS severity >=2 ] || [App apprisk >= 2] | M14: [IPS severity >=2] | N14: [IPS severity_number >=2] || [App risk_of_app >= 2]
A15: #Flows | B15: =B3 -> 78694206
A16: #Alerts | B16: 9778069 | C16: 5500009 | D16: 15278078 | E16: 15309135 | F16: 14539188 | G16: 29848323 | H16: 6990 | I16: 8738223 | J16: 24009324 | K16: 4424853 | L16: 25932651 | M16: 24194 | N16: 54938
A17: #Flow-correlated Alerts | B17: 8620288 | C17: 5136879 | D17: 13757167 | E17: 13128811 | F17: 13066562 | G17: 26195373 | H17: 6420 | I17: 7505544 | J17: 21256304 | K17: 4403661 | L17: 25655131 | M17: 22009 | N17: 49743
A18: #SIDs, #AttackID o #ThreatID | B18: 22 | C18: 71 | D18: 93 | E18: 214 | F18: 229 | G18: 443 | H18: 2 | I18: 63 | J18: 154 | K18: 26 | L18: 26 | M18: 7 | N18: 7
A19: #AppID | B19: N/A | C19: N/A | D19: N/A | E19: N/A | F19: N/A | G19: N/A | H19: N/A | I19: N/A | J19: N/A | K19: N/A | L19: 134 | M19: N/A | N19: 9
A20: #Flows_FP | B20: 3391362 | C20: 4719941 | D20: 7276338 | E20: 6879262 | F20: 6115454 | G20: 9478500 | H20: 6398 | I20: 7470907 | J20: 10855081 | K20: 4403121 | L20: 18609931 | M20: 21995 | N20: 27763
A21: #Flows_TN | B21: 75302844 | C21: 73974265 | D21: 71417868 | E21: 71814944 | F21: 72578752 | G21: 69215706 | H21: 78687808 | I21: 71223299 | J21: 67839125 | K21: 74291085 | L21: 60084275 | M21: 78672211 | N21: 78666443
A22: %Flows_FP | B22: 4.3095% | C22: 5.9978% | D22: 9.2463% | E22: 8.7418% | F22: 7.7712% | G22: 12.0447% | H22: 0.0081% | I22: 9.4936% | J22: 13.7940% | K22: 5.5952% | L22: 23.6484% | M22: 0.0279% | N22: 0.0353%
A23: %Flows_TN | B23: 95.6905% | C23: 94.0022% | D23: 90.7537% | E23: 91.2582% | F23: 92.2288% | G23: 87.9553% | H23: 99.9919% | I23: 90.5064% | J23: 86.2060% | K23: 94.4048% | L23: 76.3516% | M23: 99.9721% | N23: 99.9647%
B25: Snort [Priority <=2] | K25: FG | M25: PA
A26: Metric | B26: RS1 | C26: RS2 | D26: RS3 | E26: RS4 | F26: RS5 | G26: RS6 | H26: RS7 | I26: RS8 | J26: RS9 | K26: [IPS severity >=3] | L26: [IPS severity >=3 ] || [App apprisk >= 3] | M26: [IPS severity >=3] | N26: [IPS severity_number >=3] || [App risk_of_app >= 3]
A27: #Flows | B27: =B15 -> 78694206
A28: #Alerts | B28: 2858397 | C28: 385457 | D28: 3243854 | E28: 7886066 | F28: 4188364 | G28: 12074430 | H28: 6990 | I28: 4692620 | J28: 7929497 | K28: 4417024 | L28: 25529814 | M28: 24182 | N28: 53560
A29: #Flow-correlated Alerts | B29: 1738549 | C29: 381283 | D29: 2119832 | E29: 6020530 | F29: 3299324 | G29: 9319854 | H29: 6420 | I29: 3932063 | J29: 6045488 | K29: 4396049 | L29: 25295028 | M29: 21997 | N29: 48376
A30: #SIDs, #AttackID o #ThreatID | B30: 15 | C30: 45 | D30: 60 | E30: 155 | F30: 160 | G30: 315 | H30: 2 | I30: 39 | J30: 97 | K30: 12 | L30: 12 | M30: 6 | N30: 6
A31: #AppID | B31: N/A | C31: N/A | D31: N/A | E31: N/A | F31: N/A | G31: N/A | H31: N/A | I31: N/A | J31: N/A | K31: N/A | L31: 121 | M31: N/A | N31: 6
A32: #Flows_FP | B32: 1686398 | C32: 204091 | D32: 1724606 | E32: 3895907 | F32: 3012278 | G32: 5822763 | H32: 6398 | I32: 3922641 | J32: 5306206 | K32: 4395669 | L32: 18279194 | M32: 21983 | N32: 26434
A33: #Flows_TN | B33: 77007808 | C33: 78490115 | D33: 76969600 | E33: 74798299 | F33: 75681928 | G33: 72871443 | H33: 78687808 | I33: 74771565 | J33: 73388000 | K33: 74298537 | L33: 60415012 | M33: 78672223 | N33: 78667772
A34: %Flows_FP | B34: 2.1430% | C34: 0.2593% | D34: 2.1915% | E34: 4.9507% | F34: 3.8278% | G34: 7.3992% | H34: 0.0081% | I34: 4.9847% | J34: 6.7428% | K34: 5.5858% | L34: 23.2281% | M34: 0.0279% | N34: 0.0336%
A35: %Flows_TN | B35: 97.8570% | C35: 99.7407% | D35: 97.8085% | E35: 95.0493% | F35: 96.1722% | G35: 92.6008% | H35: 99.9919% | I35: 95.0153% | J35: 93.2572% | K35: 94.4142% | L35: 76.7719% | M35: 99.9721% | N35: 99.9664%
B37: Snort [Priority <=1] | K37: FG | M37: PA
A38: Metric | B38: RS1 | C38: RS2 | D38: RS3 | E38: RS4 | F38: RS5 | G38: RS6 | H38: RS7 | I38: RS8 | J38: RS9 | K38: [IPS severity >=4] | L38: [IPS severity >=4 ] || [App apprisk >= 4] | M38: [IPS severity >=4] | N38: [IPS severity_number >=4] || [App risk_of_app >= 4]
A39: #Flows | B39: =B27 -> 78694206
A40: #Alerts | B40: 6987 | C40: 338711 | D40: 345698 | E40: 2527690 | F40: 673827 | G40: 3201517 | H40: 6990 | I40: 21553 | J40: 360274 | K40: 4244616 | L40: 22445972 | M40: 28 | N40: 27691
A41: #Flow-correlated Alerts | B41: 6417 | C41: 338311 | D41: 344728 | E41: 2445673 | F41: 571742 | G41: 3017415 | H41: 6420 | I41: 14558 | J41: 352879 | K41: 4224161 | L41: 22211706 | M41: 28 | N41: 24694
A42: #SIDs, #AttackID o #ThreatID | B42: 3 | C42: 13 | D42: 16 | E42: 79 | F42: 42 | G42: 121 | H42: 2 | I42: 10 | J42: 24 | K42: 10 | L42: 10 | M42: 2 | N42: 2
A43: #AppID | B43: N/A | C43: N/A | D43: N/A | E43: N/A | F43: N/A | G43: N/A | H43: N/A | I43: N/A | J43: N/A | K43: N/A | L43: 103 | M43: N/A | N43: 2
...

Sheet T2 (At) S<=4, FG>=1
A1: Nº | B1: Technique | C1: Description | D1: #pcaps | E1: #flows | F1: #pcaps (#flows) | G1: RS1 [Priority <= 4 (Any)] | M1: RS2 | S1: RS3 | Y1: RS4 | AE1: RS5 | AK1: RS6 | AQ1: RS7 | AW1: RS8 | BC1: RS9 | BI1: FG [IPS severity >=1 (Any)] | BO1: FG [IPS severity >=1 (Any)] || [App apprisk >= 1 (Any)] | BV1: PA [IPS severity_number >=1 (Any)] | CB1: PA [IPS severity_number >=1 (Any)] || [App risk_of_app >= 1 (Any)]
G2: #Alerts | H2: #Flow-correlated Alerts | I2: #Flow-correlated Alerts (total) | J2: #SID | K2: %Detection_pcaps | L2: #Attack_Flows | M2: #Alerts | N2: #Flow-correlated Alerts | O2: #Flow-correlated Alerts (total) | P2: #SID | Q2: %Detection_pcaps | R2: #Attack_Flows | S2: #Alerts | T2: #Flow-correlated Alerts | U2: #Flow-correlated Alerts (total) | V2: #SID | W2: %Detection_pcaps | X2: #Attack_Flows | Y2: #Alerts | Z2: #Flow-correlated Alerts | AA2: #Flow-correlated Alerts (total) | AB2: #SID | AC2: %Detection_pcaps | AD2: #Attack_Flows | AE2: #Alerts | AF2: #Flow-correlated Alerts | AG2: #Flow-correlated Alerts (total) | AH2: #SID | AI2: %Detection_pcaps | AJ2: #Attack_Flows | AK2: #Alerts | AL2: #Flow-correlated Alerts | AM2: #Flow-correlated Alerts (total) | AN2: #SID | AO2: %Detection_pcaps | AP2: #Attack_Flows | AQ2: #Alerts | AR2: #Flow-correlated Alerts | AS2: #Flow-correlated Alerts (total) | AT2: #SID | AU2: %Detection_pcaps | AV2: #Attack_Flows | AW2: #Alerts | AX2: #Flow-correlated Alerts | AY2: #Flow-correlated Alerts (total) | AZ2: #SID | BA2: %Detection_pcaps | BB2: #Attack_Flows | BC2: #Alerts | BD2: #Flow-correlated Alerts | BE2: #Flow-correlated Alerts (total) | BF2: #SID | BG2: %Detection_pcaps | BH2: #Attack_Flows | BI2: #Alerts | BJ2: #Flow-correlated Alerts | BK2: #Flow-correlated Alerts (total) | BL2: #AttackID | BM2: %Detection_pcaps AttackID | BN2: #Attack_Flows AttackID | BO2: #Alerts | BP2: #Flow-correlated Alerts | BQ2: #Flow-correlated Alerts (total) | BR2: #AttackID | BS2: #AppID | BT2: %Detection_pcaps | BU2: #Attack_Flows | BV2: #Alerts | BW2: #Flow-correlated Alerts | BX2: #Flow-correlated Alerts (total) | BY2: #ThreatID | BZ2: %Detection_pcaps ThreatID | CA2: #Attack_Flows ThreatID | CB2: #Alerts | CC2: #Flow-correlated Alerts | CD2: #Flow-correlated Alerts (total) | CE2: #ThreatID | CF2: #AppID | CG2: %Detection_pcaps | CH2: #Attack_Flows
A3: 1 | B3: =IFERROR(VLOOKUP(A3,'Tabla 2 - Ataques detec (Imple)'!$B$3:$D$112,3,FALSE),"") -> T1001 | C3: =IFERROR(VLOOKUP(B3,Techniques!$B$3:$H$213,2,FALSE),"") -> Data Obfuscation | D3: =SUMPRODUCT( ('Tabla 2 - Ataques detec (Imple)'!$D$3:$D$112=$B3)* (LEN('Tabla 2 - Ataques detec (Imple)'!$C$3:$C$112)>0) ) -> 2 | E3: =SUMIF('Tabla 2 - Ataques detec (Imple)'!$D$3:$D$112,$B3,'Tabla 2 - Ataques detec (Imple)'!$E$3:$E$112) -> 2 | F3: =D3&" ("&E3&")" -> 2 (2) | G3: =SUMIF('Tabla 2 - Ataques detec (Imple)'!$D$3:$D$112,$B3,'Tabla 2 - Ataques detec (Imple)'!F$3:F$112) -> 9 | H3: =SUMIF('Tabla 2 - Ataques detec (Imple)'!$D$3:$D$112,$B3,'Tabla 2 - Ataques detec (Imple)'!G$3:G$112) -> 6 | I3: =H3 & " (" & G3 & ")" -> 6 (9) | J3: =SUMIF('Tabla 2 - Ataques detec (Imple)'!$D$3:$D$112,$B3,'Tabla 2 - Ataques detec (Imple)'!$H$3:$H$112) -> 6 | K3: =AVERAGEIF('Tabla 2 - Ataques detec (Imple)'!$D$3:$D$112,$B3,'Tabla 2 - Ataques detec (Imple)'!$J$3:$J$112) -> 1 | L3: =SUMIF('Tabla 2 - Ataques detec (Imple)'!$D$3:$D$112,$B3,'Tabla 2 - Ataques detec (Imple)'!$I$3:$I$112) -> 2 | M3: =SUMIF('Tabla 2 - Ataques detec (Imple)'!$D$3:$D$112,$B3,'Tabla 2 - Ataques detec (Imple)'!K$3:K$112) -> 0 | N3: =SUMIF('Tabla 2 - Ataques detec (Imple)'!$D$3:$D$112,$B3,'Tabla 2 - Ataques detec (Imple)'!L$3:L$112) -> 0 | O3: =N3 & " (" & M3 & ")" -> 0 (0) | P3: =SUMIF('Tabla 2 - Ataques detec (Imple)'!$D$3:$D$112,$B3,'Tabla 2 - Ataques detec (Imple)'!$M$3:$M$112) -> 0 | Q3: =AVERAGEIF('Tabla 2 - Ataques detec (Imple)'!$D$3:$D$112,$B3,'Tabla 2 - Ataques detec (Imple)'!$O$3:$O$112) -> 0 | R3: =SUMIF('Tabla 2 - Ataques detec (Imple)'!$D$3:$D$112,$B3,'Tabla 2 - Ataques detec (Imple)'!$N$3:$N$112) -> 0 | S3: =SUMIF('Tabla 2 - Ataques detec (Imple)'!$D$3:$D$112,$B3,'Tabla 2 - Ataques detec (Imple)'!P$3:P$112) -> 9 | T3: =SUMIF('Tabla 2 - Ataques detec (Imple)'!$D$3:$D$112,$B3,'Tabla 2 - Ataques detec (Imple)'!Q$3:Q$112) -> 6 | U3: =T3 & " (" & S3 & ")" -> 6 (9) | V3: =SUMIF('Tabla 2 - Ataques detec (Imple)'!$D$3:$D$112,$B3,'Tabla 2 - Ataques detec (Imple)'!$R$3:$R$112) -> 6 | W3: =AVERAGEIF('Tabla 2 - Ataques detec (Imple)'!$D$3:$D$112,$B3,'Tabla 2 - Ataques detec (Imple)'!$T$3:$T$112) -> 1 | X3: =SUMIF('Tabla 2 - Ataques detec (Imple)'!$D$3:$D$112,$B3,'Tabla 2 - Ataques detec (Imple)'!$S$3:$S$112) -> 2 | Y3: =SUMIF('Tabla 2 - Ataques detec (Imple)'!$D$3:$D$112,$B3,'Tabla 2 - Ataques detec (Imple)'!U$3:U$112) -> 9 | Z3: =SUMIF('Tabla 2 - Ataques detec (Imple)'!$D$3:$D$112,$B3,'Tabla 2 - Ataques detec (Imple)'!V$3:V$112) -> 6 | AA3: =Z3 & " (" & Y3 & ")" -> 6 (9) | AB3: =SUMIF('Tabla 2 - Ataques detec (Imple)'!$D$3:$D$112,$B3,'Tabla 2 - Ataques detec (Imple)'!$R$3:$R$112) -> 6 | AC3: =AVERAGEIF('Tabla 2 - Ataques detec (Imple)'!$D$3:$D$112,$B3,'Tabla 2 - Ataques detec (Imple)'!$Y$3:$Y$112) -> 1 | AD3: =SUMIF('Tabla 2 - Ataques detec (Imple)'!$D$3:$D$112,$B3,'Tabla 2 - Ataques detec (Imple)'!$X$3:$X$112) -> 2 | AE3: =SUMIF('Tabla 2 - Ataques detec (Imple)'!$D$3:$D$112,$B3,'Tabla 2 - Ataques detec (Imple)'!Z$3:Z$112) -> 8 | AF3: =SUMIF('Tabla 2 - Ataques detec (Imple)'!$D$3:$D$112,$B3,'Tabla 2 - Ataques detec (Imple)'!AA$3:AA$112) -> 4 | AG3: =AF3 & " (" & AE3 & ")" -> 4 (8) | AH3: =SUMIF('Tabla 2 - Ataques detec (Imple)'!$D$3:$D$112,$B3,'Tabla 2 - Ataques detec (Imple)'!$AB$3:$AB$112) -> 4 | AI3: =AVERAGEIF('Tabla 2 - Ataques detec (Imple)'!$D$3:$D$112,$B3,'Tabla 2 - Ataques detec (Imple)'!$AD$3:$AD$112) -> 1 | AJ3: =SUMIF('Tabla 2 - Ataques detec (Imple)'!$D$3:$D$112,$B3,'Tabla 2 - Ataques detec (Imple)'!$AC$3:$AC$112) -> 2 | AK3: =SUMIF('Tabla 2 - Ataques detec (Imple)'!$D$3:$D$112,$B3,'Tabla 2 - Ataques detec (Imple)'!AE$3:AE$112) -> 17 | AL3: =SUMIF('Tabla 2 - Ataques detec (Imple)'!$D$3:$D$112,$B3,'Tabla 2 - Ataques detec (Imple)'!AF$3:AF$112) -> 10 | AM3: =AL3 & " (" & AK3 & ")" -> 10 (17) | AN3: =SUMIF('Tabla 2 - Ataques detec (Imple)'!$D$3:$D$112,$B3,'Tabla 2 - Ataques detec (Imple)'!$AG$3:$AG$112) -> 10 | AO3: =AVERAGEIF('Tabla 2 - Ataques detec (Imple)'!$D$3:$D$112,$B3,'Tabla 2 - Ataques detec (Imple)'!$AI$3:$AI$112) -> 1 | AP3: =SUMIF('Tabla 2 - Ataques detec (Imple)'!$D$3:$D$112,$B3,'Tabla 2 - Ataques detec (Imple)'!$AH$3:$AH$112) -> 2 | AQ3: =SUMIF('Tabla 2 - Ataques detec (Imple)'!$D$3:$D$112,$B3,'Tabla 2 - Ataques detec (Imple)'!AJ$3:AJ$112) -> 0 | AR3: =SUMIF('Tabla 2 - Ataques detec (Imple)'!$D$3:$D$112,$B3,'Tabla 2 - Ataques detec (Imple)'!AK$3:AK$112) -> 0 | AS3: =AR3 & " (" & AQ3 & ")" -> 0 (0) | AT3: =SUMIF('Tabla 2 - Ataques detec (Imple)'!$D$3:$D$112,$B3,'Tabla 2 - Ataques detec (Imple)'!$AL$3:$AL$112) -> 0 | AU3: =AVERAGEIF('Tabla 2 - Ataques detec (Imple)'!$D$3:$D$112,$B3,'Tabla 2 - Ataques detec (Imple)'!$AN$3:$AN$112) -> 0 | AV3: =SUMIF('Tabla 2 - Ataques detec (Imple)'!$D$3:$D$112,$B3,'Tabla 2 - Ataques detec (Imple)'!$AM$3:$AM$112) -> 0 | AW3: =SUMIF('Tabla 2 - Ataques detec (Imple)'!$D$3:$D$112,$B3,'Tabla 2 - Ataques detec (Imple)'!AO$3:AO$112) -> 0 | AX3: =SUMIF('Tabla 2 - Ataques detec (Imple)'!$D$3:$D$112,$B3,'Tabla 2 - Ataques detec (Imple)'!AP$3:AP$112) -> 0 | AY3: =AX3 & " (" & AW3 & ")" -> 0 (0) | AZ3: =SUMIF('Tabla 2 - Ataques detec (Imple)'!$D$3:$D$112,$B3,'Tabla 2 - Ataques detec (Imple)'!$AQ$3:$AQ$112) -> 0 | BA3: =AVERAGEIF('Tabla 2 - Ataques detec (Imple)'!$D$3:$D$112,$B3,'Tabla 2 - Ataques detec (Imple)'!$AS$3:$AS$112) -> 0 | BB3: =SUMIF('Tabla 2 - Ataques detec (Imple)'!$D$3:$D$112,$B3,'Tabla 2 - Ataques detec (Imple)'!$AR$3:$AR$112) -> 0 | BC3: =SUMIF('Tabla 2 - Ataques detec (Imple)'!$D$3:$D$112,$B3,'Tabla 2 - Ataques detec (Imple)'!AT$3:AT$112) -> 9 | BD3: =SUMIF('Tabla 2 - Ataques detec (Imple)'!$D$3:$D$112,$B3,'Tabla 2 - Ataques detec (Imple)'!AU$3:AU$112) -> 6 | BE3: =BD3 & " (" & BC3 & ")" -> 6 (9) | BF3: =SUMIF('Tabla 2 - Ataques detec (Imple)'!$D$3:$D$112,$B3,'Tabla 2 - Ataques detec (Imple)'!$AV$3:$AV$112) -> 6 | BG3: =AVERAGEIF('Tabla 2 - Ataques detec (Imple)'!$D$3:$D$112,$B3,'Tabla 2 - Ataques detec (Imple)'!$AX$3:$AX$112) -> 1 | BH3: =SUMIF('Tabla 2 - Ataques detec (Imple)'!$D$3:$D$112,$B3,'Tabla 2 - Ataques detec (Imple)'!$AW$3:$AW$112) -> 2 | BI3: =SUMIF('Tabla 2 - Ataques detec (Imple)'!$D$3:$D$112,$B3,'Tabla 2 - Ataques detec (Imple)'!AY$3:AY$112) -> 1 | BJ3: =SUMIF('Tabla 2 - Ataques detec (Imple)'!$D$3:$D$112,$B3,'Tabla 2 - Ataques detec (Imple)'!AZ$3:AZ$112) -> 1 | BK3: =BJ3 & " (" & BI3 & ")" -> 1 (1) | BL3: =SUMIF('Tabla 2 - Ataques detec (Imple)'!$D$3:$D$112,$B3,'Tabla 2 - Ataques detec (Imple)'!BA$3:BA$112) -> 1 | BM3: =AVERAGEIF('Tabla 2 - Ataques detec (Imple)'!$D$3:$D$112,$B3,'Tabla 2 - Ataques detec (Imple)'!$BC$3:$BC$112) -> 0.5 | BN3: =SUMIF('Tabla 2 - Ataques detec (Imple)'!$D$3:$D$112,$B3,'Tabla 2 - Ataques detec (Imple)'!$BB$3:$BB$112) -> 1 | BO3: =SUMIF('Tabla 2 - Ataques detec (Imple)'!$D$3:$D$112,$B3,'Tabla 2 - Ataques detec (Imple)'!BD$3:BD$112) -> 3 | BP3: =SUMIF('Tabla 2 - Ataques detec (Imple)'!$D$3:$D$112,$B3,'Tabla 2 - Ataques detec (Imple)'!BE$3:BE$112) -> 3 | BQ3: =BP3 & " (" & BO3 & ")" -> 3 (3) | BR3: =SUMIF('Tabla 2 - Ataques detec (Imple)'!$D$3:$D$112,$B3,'Tabla 2 - Ataques detec (Imple)'!BF$3:BF$112) -> 1 | BS3: =SUMIF('Tabla 2 - Ataques detec (Imple)'!$D$3:$D$112,$B3,'Tabla 2 - Ataques detec (Imple)'!BG$3:BG$112) -> 2 | BT3: =AVERAGEIF('Tabla 2 - Ataques detec (Imple)'!$D$3:$D$112,$B3,'Tabla 2 - Ataques detec (Imple)'!$BI$3:$BI$112) -> 1 | BU3: =SUMIF('Tabla 2 - Ataques detec (Imple)'!$D$3:$D$112,$B3,'Tabla 2 - Ataques detec (Imple)'!$BH$3:$BH$112) -> 2 | BV3: 3 | BW3: 3 | BX3: =BW3 & " (" & BV3 & ")" -> 3 (3) | BY3: 3 | BZ3: 1 | CA3: 2 | CB3: 6 | CC3: 5 | CD3: =CC3 & " (" & CB3 & ")" -> 5 (6) | CE3: 3 | CF3: 2 | CG3: 1 | CH3: 2
A4: =A3+1 -> 2 | B4: =IFERROR(VLOOKUP(A4,'Tabla 2 - Ataques detec (Imple)'!$B$3:$D$112,3,FALSE),"") -> T1003 | C4: =IFERROR(VLOOKUP(B4,Techniques!$B$3:$H$213,2,FALSE),"") -> OS Credential Dumping | D4: =SUMPRODUCT( ('Tabla 2 - Ataques detec (Imple)'!$D$3:$D$112=$B4)* (LEN('Tabla 2 - Ataques detec (Imple)'!$C$3:$C$112)>0) ) -> 1 | E4: =SUMIF('Tabla 2 - Ataques detec (Imple)'!$D$3:$D$112,$B4,'Tabla 2 - Ataques detec (Imple)'!$E$3:$E$112) -> 3 | F4: =D4&" ("&E4&")" -> 1 (3) | G4: =SUMIF('Tabla 2 - Ataques detec (Imple)'!$D$3:$D$112,$B4,'Tabla 2 - Ataques detec (Imple)'!F$3:F$112) -> 3 | H4: =SUMIF('Tabla 2 - Ataques detec (Imple)'!$D$3:$D$112,$B4,'Tabla 2 - Ataques detec (Imple)'!G$3:G$112) -> 2 | I4: =H4 & " (" & G4 & ")" -> 2 (3) | J4: =SUMIF('Tabla 2 - Ataques detec (Imple)'!$D$3:$D$112,$B4,'Tabla 2 - Ataques detec (Imple)'!$H$3:$H$112) -> 2 | K4: =AVERAGEIF('Tabla 2 - Ataques detec (Imple)'!$D$3:$D$112,$B4,'Tabla 2 - Ataques detec (Imple)'!$J$3:$J$112) -> 1 | L4: =SUMIF('Tabla 2 - Ataques detec (Imple)'!$D$3:$D$112,$B4,'Tabla 2 - Ataques detec (Imple)'!$I$3:$I$112) -> 1 | M4: =SUMIF('Tabla 2 - Ataques detec (Imple)'!$D$3:$D$112,$B4,'Tabla 2 - Ataques detec (Imple)'!K$3:K$112) -> 0 | N4: =SUMIF('Tabla 2 - Ataques detec (Imple)'!$D$3:$D$112,$B4,'Tabla 2 - Ataques detec (Imple)'!L$3:L$112) -> 0 | O4: =N4 & " (" & M4 & ")" -> 0 (0) | P4: =SUMIF('Tabla 2 - Ataques detec (Imple)'!$D$3:$D$112,$B4,'Tabla 2 - Ataques detec (Imple)'!$M$3:$M$112) -> 0 | Q4: =AVERAGEIF('Tabla 2 - Ataques detec (Imple)'!$D$3:$D$112,$B4,'Tabla 2 - Ataques detec (Imple)'!$O$3:$O$112) -> 0 | R4: =SUMIF('Tabla 2 - Ataques detec (Imple)'!$D$3:$D$112,$B4,'Tabla 2 - Ataques detec (Imple)'!$N$3:$N$112) -> 0 | S4: =SUMIF('Tabla 2 - Ataques detec (Imple)'!$D$3:$D$112,$B4,'Tabla 2 - Ataques detec (Imple)'!P$3:P$112) -> 3 | T4: =SUMIF('Tabla 2 - Ataques detec (Imple)'!$D$3:$D$112,$B4,'Tabla 2 - Ataques detec (Imple)'!Q$3:Q$112) -> 2 | U4: =T4 & " (" & S4 & ")" -> 2 (3) | V4: =SUMIF('Tabla 2 - Ataques detec (Imple)'!$D$3:$D$112,$B4,'Tabla 2 - Ataques detec (Imple)'!$R$3:$R$112) -> 2 | W4: =AVERAGEIF('Tabla 2 - Ataques detec (Imple)'!$D$3:$D$112,$B4,'Tabla 2 - Ataques detec (Imple)'!$T$3:$T$112) -> 1 | X4: =SUMIF('Tabla 2 - Ataques detec (Imple)'!$D$3:$D$112,$B4,'Tabla 2 - Ataques detec (Imple)'!$S$3:$S$112) -> 1 | Y4: =SUMIF('Tabla 2 - Ataques detec (Imple)'!$D$3:$D$112,$B4,'Tabla 2 - Ataques detec (Imple)'!U$3:U$112) -> 4 | Z4: =SUMIF('Tabla 2 - Ataques detec (Imple)'!$D$3:$D$112,$B4,'Tabla 2 - Ataques detec (Imple)'!V$3:V$112) -> 3 | AA4: =Z4 & " (" & Y4 & ")" -> 3 (4) | AB4: =SUMIF('Tabla 2 - Ataques detec (Imple)'!$D$3:$D$112,$B4,'Tabla 2 - Ataques detec (Imple)'!$R$3:$R$112) -> 2 | AC4: =AVERAGEIF('Tabla 2 - Ataques detec (Imple)'!$D$3:$D$112,$B4,'Tabla 2 - Ataques detec (Imple)'!$Y$3:$Y$112) -> 1 | AD4: =SUMIF('Tabla 2 - Ataques detec (Imple)'!$D$3:$D$112,$B4,'Tabla 2 - Ataques detec (Imple)'!$X$3:$X$112) -> 2 | AE4: =SUMIF('Tabla 2 - Ataques detec (Imple)'!$D$3:$D$112,$B4,'Tabla 2 - Ataques detec (Imple)'!Z$3:Z$112) -> 4 | AF4: =SUMIF('Tabla 2 - Ataques detec (Imple)'!$D$3:$D$112,$B4,'Tabla 2 - Ataques detec (Imple)'!AA$3:AA$112) -> 2 | AG4: =AF4 & " (" & AE4 & ")" -> 2 (4) | AH4: =SUMIF('Tabla 2 - Ataques detec (Imple)'!$D$3:$D$112,$B4,'Tabla 2 - Ataques detec (Imple)'!$AB$3:$AB$112) -> 2 | AI4: =AVERAGEIF('Tabla 2 - Ataques detec (Imple)'!$D$3:$D$112,$B4,'Tabla 2 - Ataques detec (Imple)'!$AD$3:$AD$112) -> 1 | AJ4: =SUMIF('Tabla 2 - Ataques detec (Imple)'!$D$3:$D$112,$B4,'Tabla 2 - Ataques detec (Imple)'!$AC$3:$AC$112) -> 1 | AK4: =SUMIF('Tabla 2 - Ataques detec (Imple)'!$D$3:$D$112,$B4,'Tabla 2 - Ataques detec (Imple)'!AE$3:AE$112) -> 8 | AL4: =SUMIF('Tabla 2 - Ataques detec (Imple)'!$D$3:$D$112,$B4,'Tabla 2 - Ataques detec (Imple)'!AF$3:AF$112) -> 5 | AM4: =AL4 & " (" & AK4 & ")" -> 5 (8) | AN4: =SUMIF('Tabla 2 - Ataques detec (Imple)'!$D$3:$D$112,$B4,'Tabla 2 - Ataques detec (Imple)'!$AG$3:$AG$112) -> 5 | AO4: =AVERAGEIF('Tabla 2 - Ataques detec (Imple)'!$D$3:$D$112,$B4,'Tabla 2 - Ataques detec (Imple)'!$AI$3:$AI$112) -> 1 | AP4: =SUMIF('Tabla 2 - Ataques detec (Imple)'!$D$3:$D$112,$B4,'Tabla 2 - Ataques detec (Imple)'!$AH$3:$AH$112) -> 3 | AQ4: =SUMIF('Tabla 2 - Ataques detec (Imple)'!$D$3:$D$112,$B4,'Tabla 2 - Ataques detec (Imple)'!AJ$3:AJ$112) -> 0 | AR4: =SUMIF('Tabla 2 - Ataques detec (Imple)'!$D$3:$D$112,$B4,'Tabla 2 - Ataques detec (Imple)'!AK$3:AK$112) -> 0 | AS4: =AR4 & " (" & AQ4 & ")" -> 0 (0) | AT4: =SUMIF('Tabla 2 - Ataques detec (Imple)'!$D$3:$D$112,$B4,'Tabla 2 - Ataques detec (Imple)'!$AL$3:$AL$112) -> 0 | AU4: =AVERAGEIF('Tabla 2 - Ataques detec (Imple)'!$D$3:$D$112,$B4,'Tabla 2 - Ataques detec (Imple)'!$AN$3:$AN$112) -> 0 | AV4: =SUMIF('Tabla 2 - Ataques detec (Imple)'!$D$3:$D$112,$B4,'Tabla 2 - Ataques detec (Imple)'!$AM$3:$AM$112) -> 0 | AW4: =SUMIF('Tabla 2 - Ataques detec (Imple)'!$D$3:$D$112,$B4,'Tabla 2 - Ataques detec (Imple)'!AO$3:AO$112) -> 0 | AX4: =SUMIF('Tabla 2 - Ataques detec (Imple)'!$D$3:$D$112,$B4,'Tabla 2 - Ataques detec (Imple)'!AP$3:AP$112) -> 0 | AY4: =AX4 & " (" & AW4 & ")" -> 0 (0) | AZ4: =SUMIF('Tabla 2 - Ataques detec (Imple)'!$D$3:$D$112,$B4,'Tabla 2 - Ataques detec (Imple)'!$AQ$3:$AQ$112) -> 0 | BA4: =AVERAGEIF('Tabla 2 - Ataques detec (Imple)'!$D$3:$D$112,$B4,'Tabla 2 - Ataques detec (Imple)'!$AS$3:$AS$112) -> 0 | BB4: =SUMIF('Tabla 2 - Ataques detec (Imple)'!$D$3:$D$112,$B4,'Tabla 2 - Ataques detec (Imple)'!$AR$3:$AR$112) -> 0 | BC4: =SUMIF('Tabla 2 - Ataques detec (Imple)'!$D$3:$D$112,$B4,'Tabla 2 - Ataques detec (Imple)'!AT$3:AT$112) -> 3 | BD4: =SUMIF('Tabla 2 - Ataques detec (Imple)'!$D$3:$D$112,$B4,'Tabla 2 - Ataques detec (Imple)'!AU$3:AU$112) -> 2 | BE4: =BD4 & " (" & BC4 & ")" -> 2 (3) | BF4: =SUMIF('Tabla 2 - Ataques detec (Imple)'!$D$3:$D$112,$B4,'Tabla 2 - Ataques detec (Imple)'!$AV$3:$AV$112) -> 2 | BG4: =AVERAGEIF('Tabla 2 - Ataques detec (Imple)'!$D$3:$D$112,$B4,'Tabla 2 - Ataques detec (Imple)'!$AX$3:$AX$112) -> 1 | BH4: =SUMIF('Tabla 2 - Ataques detec (Imple)'!$D$3:$D$112,$B4,'Tabla 2 - Ataques detec (Imple)'!$AW$3:$AW$112) -> 1 | BI4: =SUMIF('Tabla 2 - Ataques detec (Imple)'!$D$3:$D$112,$B4,'Tabla 2 - Ataques detec (Imple)'!AY$3:AY$112) -> 0 | BJ4: =SUMIF('Tabla 2 - Ataques detec (Imple)'!$D$3:$D$112,$B4,'Tabla 2 - Ataques detec (Imple)'!AZ$3:AZ$112) -> 0 | BK4: =BJ4 & " (" & BI4 & ")" -> 0 (0) | BL4: =SUMIF('Tabla 2 - Ataques detec (Imple)'!$D$3:$D$112,$B4,'Tabla 2 - Ataques detec (Imple)'!BA$3:BA$112) -> 0 | BM4: =AVERAGEIF('Tabla 2 - Ataques detec (Imple)'!$D$3:$D$112,$B4,'Tabla 2 - Ataques detec (Imple)'!$BC$3:$BC$112) -> 0 | BN4: =SUMIF('Tabla 2 - Ataques detec (Imple)'!$D$3:$D$112,$B4,'Tabla 2 - Ataques detec (Imple)'!$BB$3:$BB$112) -> 0 | BO4: =SUMIF('Tabla 2 - Ataques detec (Imple)'!$D$3:$D$112,$B4,'Tabla 2 - Ataques detec (Imple)'!BD$3:BD$112) -> 3 | BP4: =SUMIF('Tabla 2 - Ataques detec (Imple)'!$D$3:$D$112,$B4,'Tabla 2 - Ataques detec (Imple)'!BE$3:BE$112) -> 3 | BQ4: =BP4 & " (" & BO4 & ")" -> 3 (3) | BR4: =SUMIF('Tabla 2 - Ataques detec (Imple)'!$D$3:$D$112,$B4,'Tabla 2 - Ataques detec (Imple)'!BF$3:BF$112) -> 0 | BS4: =SUMIF('Tabla 2 - Ataques detec (Imple)'!$D$3:$D$112,$B4,'Tabla 2 - Ataques detec (Imple)'!BG$3:BG$112) -> 3 | BT4: =AVERAGEIF('Tabla 2 - Ataques detec (Imple)'!$D$3:$D$112,$B4,'Tabla 2 - Ataques detec (Imple)'!$BI$3:$BI$112) -> 1 | BU4: =SUMIF('Tabla 2 - Ataques detec (Imple)'!$D$3:$D$112,$B4,'Tabla 2 - Ataques detec (Imple)'!$BH$3:$BH$112) -> 3 | BV4: 0 | BW4: 0 | BX4: =BW4 & " (" & BV4 & ")" -> 0 (0) | BY4: 0 | BZ4: 0 | CA4: 0 | CB4: 0 | CC4: 0 | CD4: =CC4 & " (" & CB4 & ")" -> 0 (0) | CE4: 0 | CF4: 0 | CG4: 0 | CH4: 0
A5: =A4+1 -> 3 | B5: =IFERROR(VLOOKUP(A5,'Tabla 2 - Ataques detec (Imple)'!$B$3:$D$112,3,FALSE),"") -> T1008 | C5: =IFERROR(VLOOKUP(B5,Techniques!$B$3:$H$213,2,FALSE),"") -> Fallback Channels | D5: =SUMPRODUCT( ('Tabla 2 - Ataques detec (Imple)'!$D$3:$D$112=$B5)* (LEN('Tabla 2 - Ataques detec (Imple)'!$C$3:$C$112)>0) ) -> 1 | E5: =SUMIF('Tabla 2 - Ataques detec (Imple)'!$D$3:$D$112,$B5,'Tabla 2 - Ataques detec (Imple)'!$E$3:$E$112) -> 6 | F5: =D5&" ("&E5&")" -> 1 (6) | G5: =SUMIF('Tabla 2 - Ataques detec (Imple)'!$D$3:$D$112,$B5,'Tabla 2 - Ataques detec (Imple)'!F$3:F$112) -> 15 | H5: =SUMIF('Tabla 2 - Ataques detec (Imple)'!$D$3:$D$112,$B5,'Tabla 2 - Ataques detec (Imple)'!G$3:G$112) -> 1 | I5: =H5 & " (" & G5 & ")" -> 1 (15) | J5: =SUMIF('Tabla 2 - Ataques detec (Imple)'!$D$3:$D$112,$B5,'Tabla 2 - Ataques detec (Imple)'!$H$3:$H$112) -> 1 | K5: =AVERAGEIF('Tabla 2 - Ataques detec (Imple)'!$D$3:$D$112,$B5,'Tabla 2 - Ataques detec (Imple)'!$J$3:$J$112) -> 1 | L5: =SUMIF('Tabla 2 - Ataques detec (Imple)'!$D$3:$D$112,$B5,'Tabla 2 - Ataques detec (Imple)'!$I$3:$I$112) -> 1 | M5: =SUMIF('Tabla 2 - Ataques detec (Imple)'!$D$3:$D$112,$B5,'Tabla 2 - Ataques detec (Imple)'!K$3:K$112) -> 17 | N5: =SUMIF('Tabla 2 - Ataques detec (Imple)'!$D$3:$D$112,$B5,'Tabla 2 - Ataques detec (Imple)'!L$3:L$112) -> 7 | O5: =N5 & " (" & M5 & ")" -> 7 (17) | P5: =SUMIF('Tabla 2 - Ataques detec (Imple)'!$D$3:$D$112,$B5,'Tabla 2 - Ataques detec (Imple)'!$M$3:$M$112) -> 4 | Q5: =AVERAGEIF('Tabla 2 - Ataques detec (Imple)'!$D$3:$D$112,$B5,'Tabla 2 - Ataques detec (Imple)'!$O$3:$O$112) -> 1 | R5: =SUMIF('Tabla 2 - Ataques detec (Imple)'!$D$3:$D$112,$B5,'Tabla 2 - Ataques detec (Imple)'!$N$3:$N$112) -> 3 | S5: =SUMIF('Tabla 2 - Ataques detec (Imple)'!$D$3:$D$112,$B5,'Tabla 2 - Ataques detec (Imple)'!P$3:P$112) -> 32 | T5: =SUMIF('Tabla 2 - Ataques detec (Imple)'!$D$3:$D$112,$B5,'Tabla 2 - Ataques detec (Imple)'!Q$3:Q$112) -> 8 | U5: =T5 & " (" & S5 & ")" -> 8 (32) | V5: =SUMIF('Tabla 2 - Ataques detec (Imple)'!$D$3:$D$112,$B5,'Tabla 2 - Ataques detec (Imple)'!$R$3:$R$112) -> 5 | W5: =AVERAGEIF('Tabla 2 - Ataques detec (Imple)'!$D$3:$D$112,$B5,'Tabla 2 - Ataques detec (Imple)'!$T$3:$T$112) -> 1 | X5: =SUMIF('Tabla 2 - Ataques detec (Imple)'!$D$3:$D$112,$B5,'Tabla 2 - Ataques detec (Imple)'!$S$3:$S$112) -> 3 | Y5: =SUMIF('Tabla 2 - Ataques detec (Imple)'!$D$3:$D$112,$B5,'Tabla 2 - Ataques detec (Imple)'!U$3:U$112) -> 99 | Z5: =SUMIF('Tabla 2 - Ataques detec (Imple)'!$D$3:$D$112,$B5,'Tabla 2 - Ataques detec (Imple)'!V$3:V$112) -> 4 | AA5: =Z5 & " (" & Y5 & ")" -> 4 (99) | AB5: =SUMIF('Tabla 2 - Ataques detec (Imple)'!$D$3:$D$112,$B5,'Tabla 2 - Ataques detec (Imple)'!$R$3:$R$112) -> 5 | AC5: =AVERAGEIF('Tabla 2 - Ataques detec (Imple)'!$D$3:$D$112,$B5,'Tabla 2 - Ataques detec (Imple)'!$Y$3:$Y$112) -> 1 | AD5: =SUMIF('Tabla 2 - Ataques detec (Imple)'!$D$3:$D$112,$B5,'Tabla 2 - Ataques detec (Imple)'!$X$3:$X$112) -> 3 | AE5: =SUMIF('Tabla 2 - Ataques detec (Imple)'!$D$3:$D$112,$B5,'Tabla 2 - Ataques detec (Imple)'!Z$3:Z$112) -> 57 | AF5: =SUMIF('Tabla 2 - Ataques detec (Imple)'!$D$3:$D$112,$B5,'Tabla 2 - Ataques detec (Imple)'!AA$3:AA$112) -> 28 | AG5: =AF5 & " (" & AE5 & ")" -> 28 (57) | AH5: =SUMIF('Tabla 2 - Ataques detec (Imple)'!$D$3:$D$112,$B5,'Tabla 2 - Ataques detec (Imple)'!$AB$3:$AB$112) -> 22 | AI5: =AVERAGEIF('Tabla 2 - Ataques detec (Imple)'!$D$3:$D$112,$B5,'Tabla 2 - Ataques detec (Imple)'!$AD$3:$AD$112) -> 1 | AJ5: =SUMIF('Tabla 2 - Ataques detec (Imple)'!$D$3:$D$112,$B5,'Tabla 2 - Ataques detec (Imple)'!$AC$3:$AC$112) -> 5 | AK5: =SUMIF('Tabla 2 - Ataques detec (Imple)'!$D$3:$D$112,$B5,'Tabla 2 - Ataques detec (Imple)'!AE$3:AE$112) -> 156 | AL5: =SUMIF('Tabla 2 - Ataques detec (Imple)'!$D$3:$D$112,$B5,'Tabla 2 - Ataques detec (Imple)'!AF$3:AF$112) -> 32 | AM5: =AL5 & " (" & AK5 & ")" -> 32 (156) | AN5: =SUMIF('Tabla 2 - Ataques detec (Imple)'!$D$3:$D$112,$B5,'Tabla 2 - Ataques detec (Imple)'!$AG$3:$AG$112) -> 25 | AO5: =AVERAGEIF('Tabla 2 - Ataques detec (Imple)'!$D$3:$D$112,$B5,'Tabla 2 - Ataques detec (Imple)'!$AI$3:$AI$112) -> 1 | AP5: =SUMIF('Tabla 2 - Ataques detec (Imple)'!$D$3:$D$112,$B5,'Tabla 2 - Ataques detec (Imple)'!$AH$3:$AH$112) -> 5 | AQ5: =SUMIF('Tabla 2 - Ataques detec (Imple)'!$D$3:$D$112,$B5,'Tabla 2 - Ataques detec (Imple)'!AJ$3:AJ$112) -> 0 | AR5: =SUMIF('Tabla 2 - Ataques detec (Imple)'!$D$3:$D$112,$B5,'Tabla 2 - Ataques detec (Imple)'!AK$3:AK$112) -> 0 | AS5: =AR5 & " (" & AQ5 & ")" -> 0 (0) | AT5: =SUMIF('Tabla 2 - Ataques detec (Imple)'!$D$3:$D$112,$B5,'Tabla 2 - Ataques detec (Imple)'!$AL$3:$AL$112) -> 0 | AU5: =AVERAGEIF('Tabla 2 - Ataques detec (Imple)'!$D$3:$D$112,$B5,'Tabla 2 - Ataques detec (Imple)'!$AN$3:$AN$112) -> 0 | AV5: =SUMIF('Tabla 2 - Ataques detec (Imple)'!$D$3:$D$112,$B5,'Tabla 2 - Ataques detec (Imple)'!$AM$3:$AM$112) -> 0 | AW5: =SUMIF('Tabla 2 - Ataques detec (Imple)'!$D$3:$D$112,$B5,'Tabla 2 - Ataques detec (Imple)'!AO$3:AO$112) -> 0 | AX5: =SUMIF('Tabla 2 - Ataques detec (Imple)'!$D$3:$D$112,$B5,'Tabla 2 - Ataques detec (Imple)'!AP$3:AP$112) -> 0 | AY5: =AX5 & " (" & AW5 & ")" -> 0 (0) | AZ5: =SUMIF('Tabla 2 - Ataques detec (Imple)'!$D$3:$D$112,$B5,'Tabla 2 - Ataques detec (Imple)'!$AQ$3:$AQ$112) -> 0 | BA5: =AVERAGEIF('Tabla 2 - Ataques detec (Imple)'!$D$3:$D$112,$B5,'Tabla 2 - Ataques detec (Imple)'!$AS$3:$AS$112) -> 0 | BB5: =SUMIF('Tabla 2 - Ataques detec (Imple)'!$D$3:$D$112,$B5,'Tabla 2 - Ataques detec (Imple)'!$AR$3:$AR$112) -> 0 | BC5: =SUMIF('Tabla 2 - Ataques detec (Imple)'!$D$3:$D$112,$B5,'Tabla 2 - Ataques detec (Imple)'!AT$3:AT$112) -> 32 | BD5: =SUMIF('Tabla 2 - Ataques detec (Imple)'!$D$3:$D$112,$B5,'Tabla 2 - Ataques detec (Imple)'!AU$3:AU$112) -> 8 | BE5: =BD5 & " (" & BC5 & ")" -> 8 (32) | BF5: =SUMIF('Tabla 2 - Ataques detec (Imple)'!$D$3:$D$112,$B5,'Tabla 2 - Ataques detec (Imple)'!$AV$3:$AV$112) -> 5 | BG5: =AVERAGEIF('Tabla 2 - Ataques detec (Imple)'!$D$3:$D$112,$B5,'Tabla 2 - Ataques detec (Imple)'!$AX$3:$AX$112) -> 1 | BH5: =SUMIF('Tabla 2 - Ataques detec (Imple)'!$D$3:$D$112,$B5,'Tabla 2 - Ataques detec (Imple)'!$AW$3:$AW$112) -> 3 | BI5: =SUMIF('Tabla 2 - Ataques detec (Imple)'!$D$3:$D$112,$B5,'Tabla 2 - Ataques detec (Imple)'!AY$3:AY$112) -> 6 | BJ5: =SUMIF('Tabla 2 - Ataques detec (Imple)'!$D$3:$D$112,$B5,'Tabla 2 - Ataques detec (Imple)'!AZ$3:AZ$112) -> 4 | BK5: =BJ5 & " (" & BI5 & ")" -> 4 (6) | BL5: =SUMIF('Tabla 2 - Ataques detec (Imple)'!$D$3:$D$112,$B5,'Tabla 2 - Ataques detec (Imple)'!BA$3:BA$112) -> 2 | BM5: =AVERAGEIF('Tabla 2 - Ataques detec (Imple)'!$D$3:$D$112,$B5,'Tabla 2 - Ataques detec (Imple)'!$BC$3:$BC$112) -> 1 | BN5: =SUMIF('Tabla 2 - Ataques detec (Imple)'!$D$3:$D$112,$B5,'Tabla 2 - Ataques detec (Imple)'!$BB$3:$BB$112) -> 2 | BO5: =SUMIF('Tabla 2 - Ataques detec (Imple)'!$D$3:$D$112,$B5,'Tabla 2 - Ataques detec (Imple)'!BD$3:BD$112) -> 17 | BP5: =SUMIF('Tabla 2 - Ataques detec (Imple)'!$D$3:$D$112,$B5,'Tabla 2 - Ataques detec (Imple)'!BE$3:BE$112) -> 12 | BQ5: =BP5 & " (" & BO5 & ")" -> 12 (17) | BR5: =SUMIF('Tabla 2 - Ataques detec (Imple)'!$D$3:$D$112,$B5,'Tabla 2 - Ataques detec (Imple)'!BF$3:BF$112) -> 2 | BS5: =SUMIF('Tabla 2 - Ataques detec (Imple)'!$D$3:$D$112,$B5,'Tabla 2 - Ataques detec (Imple)'!BG$3:BG$112) -> 6 | BT5: =AVERAGEIF('Tabla 2 - Ataques detec (Imple)'!$D$3:$D$112,$B5,'Tabla 2 - Ataques detec (Imple)'!$BI$3:$BI$112) -> 1 | BU5: =SUMIF('Tabla 2 - Ataques detec (Imple)'!$D$3:$D$112,$B5,'Tabla 2 - Ataques detec (Imple)'!$BH$3:$BH$112) -> 5 | BV5: 11 | BW5: 5 | BX5: =BW5 & " (" & BV5 & ")" -> 5 (11) | BY5: 3 | BZ5: 1 | CA5: 3 | CB5: 22 | CC5: 8 | CD5: =CC5 & " (" & CB5 & ")" -> 8 (22) | CE5: 3 | CF5: 2 | CG5: 1 | CH5: 3
A6: =A5+1 -> 4 | B6: =IFERROR(VLOOKUP(A6,'Tabla 2 - Ataques detec (Imple)'!$B$3:$D$112,3,FALSE),"") -> T1011 | C6: =IFERROR(VLOOKUP(B6,Techniques!$B$3:$H$213,2,FALSE),"") -> Exfiltration Over Other Network Medium | D6: =SUMPRODUCT( ('Tabla 2 - Ataques detec (Imple)'!$D$3:$D$112=$B6)* (LEN('Tabla 2 - Ataques detec (Imple)'!$C$3:$C$112)>0) ) -> 1 | E6: =SUMIF('Tabla 2 - Ataques detec (Imple)'!$D$3:$D$112,$B6,'Tabla 2 - Ataques detec (Imple)'!$E$3:$E$112) -> 1 | F6: =D6&" ("&E6&")" -> 1 (1) | G6: =SUMIF('Tabla 2 - Ataques detec (Imple)'!$D$3:$D$112,$B6,'Tabla 2 - Ataques detec (Imple)'!F$3:F$112) -> 1 | H6: =SUMIF('Tabla 2 - Ataques detec (Imple)'!$D$3:$D$112,$B6,'Tabla 2 - Ataques detec (Imple)'!G$3:G$112) -> 1 | I6: =H6 & " (" & G6 & ")" -> 1 (1) | J6: =SUMIF('Tabla 2 - Ataques detec (Imple)'!$D$3:$D$112,$B6,'Tabla 2 - Ataques detec (Imple)'!$H$3:$H$112) -> 1 | K6: =AVERAGEIF('Tabla 2 - Ataques detec (Imple)'!$D$3:$D$112,$B6,'Tabla 2 - Ataques detec (Imple)'!$J$3:$J$112) -> 1 | L6: =SUMIF('Tabla 2 - Ataques detec (Imple)'!$D$3:$D$112,$B6,'Tabla 2 - Ataques detec (Imple)'!$I$3:$I$112) -> 1 | M6: =SUMIF('Tabla 2 - Ataques detec (Imple)'!$D$3:$D$112,$B6,'Tabla 2 - Ataques detec (Imple)'!K$3:K$112) -> 0 | N6: =SUMIF('Tabla 2 - Ataques detec (Imple)'!$D$3:$D$112,$B6,'Tabla 2 - Ataques detec (Imple)'!L$3:L$112) -> 0 | O6: =N6 & " (" & M6 & ")" -> 0 (0) | P6: =SUMIF('Tabla 2 - Ataques detec (Imple)'!$D$3:$D$112,$B6,'Tabla 2 - Ataques detec (Imple)'!$M$3:$M$112) -> 0 | Q6: =AVERAGEIF('Tabla 2 - Ataques detec (Imple)'!$D$3:$D$112,$B6,'Tabla 2 - Ataques detec (Imple)'!$O$3:$O$112) -> 0 | R6: =SUMIF('Tabla 2 - Ataques detec (Imple)'!$D$3:$D$112,$B6,'Tabla 2 - Ataques detec (Imple)'!$N$3:$N$112) -> 0 | S6: =SUMIF('Tabla 2 - Ataques detec (Imple)'!$D$3:$D$112,$B6,'Tabla 2 - Ataques detec (Imple)'!P$3:P$112) -> 1 | T6: =SUMIF('Tabla 2 - Ataques detec (Imple)'!$D$3:$D$112,$B6,'Tabla 2 - Ataques detec (Imple)'!Q$3:Q$112) -> 1 | U6: =T6 & " (" & S6 & ")" -> 1 (1) | V6: =SUMIF('Tabla 2 - Ataques detec (Imple)'!$D$3:$D$112,$B6,'Tabla 2 - Ataques detec (Imple)'!$R$3:$R$112) -> 1 | W6: =AVERAGEIF('Tabla 2 - Ataques detec (Imple)'!$D$3:$D$112,$B6,'Tabla 2 - Ataques detec (Imple)'!$T$3:$T$112) -> 1 | X6: =SUMIF('Tabla 2 - Ataques detec (Imple)'!$D$3:$D$112,$B6,'Tabla 2 - Ataques detec (Imple)'!$S$3:$S$112) -> 1 | Y6: =SUMIF('Tabla 2 - Ataques detec (Imple)'!$D$3:$D$112,$B6,'Tabla 2 - Ataques detec (Imple)'!U$3:U$112) -> 1 | Z6: =SUMIF('Tabla 2 - Ataques detec (Imple)'!$D$3:$D$112,$B6,'Tabla 2 - Ataques detec (Imple)'!V$3:V$112) -> 1 | AA6: =Z6 & " (" & Y6 & ")" -> 1 (1) | AB6: =SUMIF('Tabla 2 - Ataques detec (Imple)'!$D$3:$D$112,$B6,'Tabla 2 - Ataques detec (Imple)'!$R$3:$R$112) -> 1 | AC6: =AVERAGEIF('Tabla 2 - Ataques detec (Imple)'!$D$3:$D$112,$B6,'Tabla 2 - Ataques detec (Imple)'!$Y$3:$Y$112) -> 1 | AD6: =SUMIF('Tabla 2 - Ataques detec (Imple)'!$D$3:$D$112,$B6,'Tabla 2 - Ataques detec (Imple)'!$X$3:$X$112) -> 1 | AE6: =SUMIF('Tabla 2 - Ataques detec (Imple)'!$D$3:$D$112,$B6,'Tabla 2 - Ataques detec (Imple)'!Z$3:Z$112) -> 4 | AF6: =SUMIF('Tabla 2 - Ataques detec (Imple)'!$D$3:$D$112,$B6,'Tabla 2 - Ataques detec (Imple)'!AA$3:AA$112) -> 2 | AG6: =AF6 & " (" & AE6 & ")" -> 2 (4) | AH6: =SUMIF('Tabla 2 - Ataques detec (Imple)'!$D$3:$D$112,$B6,'Tabla 2 - Ataques detec (Imple)'!$AB$3:$AB$112) -> 2 | AI6: =AVERAGEIF('Tabla 2 - Ataques detec (Imple)'!$D$3:$D$112,$B6,'Tabla 2 - Ataques detec (Imple)'!$AD$3:$AD$112) -> 1 | AJ6: =SUMIF('Tabla 2 - Ataques detec (Imple)'!$D$3:$D$112,$B6,'Tabla 2 - Ataques detec (Imple)'!$AC$3:$AC$112) -> 1 | AK6: =SUMIF('Tabla 2 - Ataques detec (Imple)'!$D$3:$D$112,$B6,'Tabla 2 - Ataques detec (Imple)'!AE$3:AE$112) -> 5 | AL6: =SUMIF('Tabla 2 - Ataques detec (Imple)'!$D$3:$D$112,$B6,'Tabla 2 - Ataques detec (Imple)'!AF$3:AF$112) -> 3 | AM6: =AL6 & " (" & AK6 & ")" -> 3 (5) | AN6: =SUMIF('Tabla 2 - Ataques detec (Imple)'!$D$3:$D$112,$B6,'Tabla 2 - Ataques detec (Imple)'!$AG$3:$AG$112) -> 3 | AO6: =AVERAGEIF('Tabla 2 - Ataques detec (Imple)'!$D$3:$D$112,$B6,'Tabla 2 - Ataques detec (Imple)'!$AI$3:$AI$112) -> 1 | AP6: =SUMIF('Tabla 2 - Ataques detec (Imple)'!$D$3:$D$112,$B6,'Tabla 2 - Ataques detec (Imple)'!$AH$3:$AH$112) -> 1 | AQ6: =SUMIF('Tabla 2 - Ataques detec (Imple)'!$D$3:$D$112,$B6,'Tabla 2 - Ataques detec (Imple)'!AJ$3:AJ$112) -> 0 | AR6: =SUMIF('Tabla 2 - Ataques detec (Imple)'!$D$3:$D$112,$B6,'Tabla 2 - Ataques detec (Imple)'!AK$3:AK$112) -> 0 | AS6: =AR6 & " (" & AQ6 & ")" -> 0 (0) | AT6: =SUMIF('Tabla 2 - Ataques detec (Imple)'!$D$3:$D$112,$B6,'Tabla 2 - Ataques detec (Imple)'!$AL$3:$AL$112) -> 0 | AU6: =AVERAGEIF('Tabla 2 - Ataques detec (Imple)'!$D$3:$D$112,$B6,'Tabla 2 - Ataques detec (Imple)'!$AN$3:$AN$112) -> 0 | AV6: =SUMIF('Tabla 2 - Ataques detec (Imple)'!$D$3:$D$112,$B6,'Tabla 2 - Ataques detec (Imple)'!$AM$3:$AM$112) -> 0 | AW6: =SUMIF('Tabla 2 - Ataques detec (Imple)'!$D$3:$D$112,$B6,'Tabla 2 - Ataques detec (Imple)'!AO$3:AO$112) -> 0 | AX6: =SUMIF('Tabla 2 - Ataques detec (Imple)'!$D$3:$D$112,$B6,'Tabla 2 - Ataques detec (Imple)'!AP$3:AP$112) -> 0 | AY6: =AX6 & " (" & AW6 & ")" -> 0 (0) | AZ6: =SUMIF('Tabla 2 - Ataques detec (Imple)'!$D$3:$D$112,$B6,'Tabla 2 - Ataques detec (Imple)'!$AQ$3:$AQ$112) -> 0 | BA6: =AVERAGEIF('Tabla 2 - Ataques detec (Imple)'!$D$3:$D$112,$B6,'Tabla 2 - Ataques detec (Imple)'!$AS$3:$AS$112) -> 0 | BB6: =SUMIF('Tabla 2 - Ataques detec (Imple)'!$D$3:$D$112,$B6,'Tabla 2 - Ataques detec (Imple)'!$AR$3:$AR$112) -> 0 | BC6: =SUMIF('Tabla 2 - Ataques detec (Imple)'!$D$3:$D$112,$B6,'Tabla 2 - Ataques detec (Imple)'!AT$3:AT$112) -> 1 | BD6: =SUMIF('Tabla 2 - Ataques detec (Imple)'!$D$3:$D$112,$B6,'Tabla 2 - Ataques detec (Imple)'!AU$3:AU$112) -> 1 | BE6: =BD6 & " (" & BC6 & ")" -> 1 (1) | BF6: =SUMIF('Tabla 2 - Ataques detec (Imple)'!$D$3:$D$112,$B6,'Tabla 2 - Ataques detec (Imple)'!$AV$3:$AV$112) -> 1 | BG6: =AVERAGEIF('Tabla 2 - Ataques detec (Imple)'!$D$3:$D$112,$B6,'Tabla 2 - Ataques detec (Imple)'!$AX$3:$AX$112) -> 1 | BH6: =SUMIF('Tabla 2 - Ataques detec (Imple)'!$D$3:$D$112,$B6,'Tabla 2 - Ataques detec (Imple)'!$AW$3:$AW$112) -> 1 | BI6: =SUMIF('Tabla 2 - Ataques detec (Imple)'!$D$3:$D$112,$B6,'Tabla 2 - Ataques detec (Imple)'!AY$3:AY$112) -> 0 | BJ6: =SUMIF('Tabla 2 - Ataques detec (Imple)'!$D$3:$D$112,$B6,'Tabla 2 - Ataques detec (Imple)'!AZ$3:AZ$112) -> 0 | BK6: =BJ6 & " (" & BI6 & ")" -> 0 (0) | BL6: =SUMIF('Tabla 2 - Ataques detec (Imple)'!$D$3:$D$112,$B6,'Tabla 2 - Ataques detec (Imple)'!BA$3:BA$112) -> 0 | BM6: =AVERAGEIF('Tabla 2 - Ataques detec (Imple)'!$D$3:$D$112,$B6,'Tabla 2 - Ataques detec (Imple)'!$BC$3:$BC$112) -> 0 | BN6: =SUMIF('Tabla 2 - Ataques detec (Imple)'!$D$3:$D$112,$B6,'Tabla 2 - Ataques detec (Imple)'!$BB$3:$BB$112) -> 0 | BO6: =SUMIF('Tabla 2 - Ataques detec (Imple)'!$D$3:$D$112,$B6,'Tabla 2 - Ataques detec (Imple)'!BD$3:BD$112) -> 0 | BP6: =SUMIF('Tabla 2 - Ataques detec (Imple)'!$D$3:$D$112,$B6,'Tabla 2 - Ataques detec (Imple)'!BE$3:BE$112) -> 0 | BQ6: =BP6 & " (" & BO6 & ")" -> 0 (0) | BR6: =SUMIF('Tabla 2 - Ataques detec (Imple)'!$D$3:$D$112,$B6,'Tabla 2 - Ataques detec (Imple)'!BF$3:BF$112) -> 0 | BS6: =SUMIF('Tabla 2 - Ataques detec (Imple)'!$D$3:$D$112,$B6,'Tabla 2 - Ataques detec (Imple)'!BG$3:BG$112) -> 0 | BT6: =AVERAGEIF('Tabla 2 - Ataques detec (Imple)'!$D$3:$D$112,$B6,'Tabla 2 - Ataques detec (Imple)'!$BI$3:$BI$112) -> 0 | BU6: =SUMIF('Tabla 2 - Ataques detec (Imple)'!$D$3:$D$112,$B6,'Tabla 2 - Ataques detec (Imple)'!$BH$3:$BH$112) -> 0 | BV6: 0 | BW6: 0 | BX6: =BW6 & " (" & BV6 & ")" -> 0 (0) | BY6: 0 | BZ6: 0 | CA6: 0 | CB6: 0 | CC6: 0 | CD6: =CC6 & " (" & CB6 & ")" -> 0 (0) | CE6: 0 | CF6: 0 | CG6: 0 | CH6: 0
A7: =A6+1 -> 5 | B7: =IFERROR(VLOOKUP(A7,'Tabla 2 - Ataques detec (Imple)'!$B$3:$D$112,3,FALSE),"") -> T1018 | C7: =IFERROR(VLOOKUP(B7,Techniques!$B$3:$H$213,2,FALSE),"") -> Remote System Discovery | D7: =SUMPRODUCT( ('Tabla 2 - Ataques detec (Imple)'!$D$3:$D$112=$B7)* (LEN('Tabla 2 - Ataques detec (Imple)'!$C$3:$C$112)>0) ) -> 1 | E7: =SUMIF('Tabla 2 - Ataques detec (Imple)'!$D$3:$D$112,$B7,'Tabla 2 - Ataques detec (Imple)'!$E$3:$E$112) -> 1002 | F7: =D7&" ("&E7&")" -> 1 (1002) | G7: =SUMIF('Tabla 2 - Ataques detec (Imple)'!$D$3:$D$112,$B7,'Tabla 2 - Ataques detec (Imple)'!F$3:F$112) -> 0 | H7: =SUMIF('Tabla 2 - Ataques detec (Imple)'!$D$3:$D$112,$B7,'Tabla 2 - Ataques detec (Imple)'!G$3:G$112) -> 0 | I7: =H7 & " (" & G7 & ")" -> 0 (0) | J7: =SUMIF('Tabla 2 - Ataques detec (Imple)'!$D$3:$D$112,$B7,'Tabla 2 - Ataques detec (Imple)'!$H$3:$H$112) -> 0 | K7: =AVERAGEIF('Tabla 2 - Ataques detec (Imple)'!$D$3:$D$112,$B7,'Tabla 2 - Ataques detec (Imple)'!$J$3:$J$112) -> 0 | L7: =SUMIF('Tabla 2 - Ataques detec (Imple)'!$D$3:$D$112,$B7,'Tabla 2 - Ataques detec (Imple)'!$I$3:$I$112) -> 0 | M7: =SUMIF('Tabla 2 - Ataques detec (Imple)'!$D$3:$D$112,$B7,'Tabla 2 - Ataques detec (Imple)'!K$3:K$112) -> 6 | N7: =SUMIF('Tabla 2 - Ataques detec (Imple)'!$D$3:$D$112,$B7,'Tabla 2 - Ataques detec (Imple)'!L$3:L$112) -> 6 | O7: =N7 & " (" & M7 & ")" -> 6 (6) | P7: =SUMIF('Tabla 2 - Ataques detec (Imple)'!$D$3:$D$112,$B7,'Tabla 2 - Ataques detec (Imple)'!$M$3:$M$112) -> 6 | Q7: =AVERAGEIF('Tabla 2 - Ataques detec (Imple)'!$D$3:$D$112,$B7,'Tabla 2 - Ataques detec (Imple)'!$O$3:$O$112) -> 1 | R7: =SUMIF('Tabla 2 - Ataques detec (Imple)'!$D$3:$D$112,$B7,'Tabla 2 - Ataques detec (Imple)'!$N$3:$N$112) -> 6 | S7: =SUMIF('Tabla 2 - Ataques detec (Imple)'!$D$3:$D$112,$B7,'Tabla 2 - Ataques detec (Imple)'!P$3:P$112) -> 6 | T7: =SUMIF('Tabla 2 - Ataques detec (Imple)'!$D$3:$D$112,$B7,'Tabla 2 - Ataques detec (Imple)'!Q$3:Q$112) -> 6 | U7: =T7 & " (" & S7 & ")" -> 6 (6) | V7: =SUMIF('Tabla 2 - Ataques detec (Imple)'!$D$3:$D$112,$B7,'Tabla 2 - Ataques detec (Imple)'!$R$3:$R$112) -> 6 | W7: =AVERAGEIF('Tabla 2 - Ataques detec (Imple)'!$D$3:$D$112,$B7,'Tabla 2 - Ataques detec (Imple)'!$T$3:$T$112) -> 1 | X7: =SUMIF('Tabla 2 - Ataques detec (Imple)'!$D$3:$D$112,$B7,'Tabla 2 - Ataques detec (Imple)'!$S$3:$S$112) -> 6 | Y7: =SUMIF('Tabla 2 - Ataques detec (Imple)'!$D$3:$D$112,$B7,'Tabla 2 - Ataques detec (Imple)'!U$3:U$112) -> 2 | Z7: =SUMIF('Tabla 2 - Ataques detec (Imple)'!$D$3:$D$112,$B7,'Tabla 2 - Ataques detec (Imple)'!V$3:V$112) -> 2 | AA7: =Z7 & " (" & Y7 & ")" -> 2 (2) | AB7: =SUMIF('Tabla 2 - Ataques detec (Imple)'!$D$3:$D$112,$B7,'Tabla 2 - Ataques detec (Imple)'!$R$3:$R$112) -> 6 | AC7: =AVERAGEIF('Tabla 2 - Ataques detec (Imple)'!$D$3:$D$112,$B7,'Tabla 2 - Ataques detec (Imple)'!$Y$3:$Y$112) -> 1 | AD7: =SUMIF('Tabla 2 - Ataques detec (Imple)'!$D$3:$D$112,$B7,'Tabla 2 - Ataques detec (Imple)'!$X$3:$X$112) -> 2 | AE7: =SUMIF('Tabla 2 - Ataques detec (Imple)'!$D$3:$D$112,$B7,'Tabla 2 - Ataques detec (Imple)'!Z$3:Z$112) -> 11 | AF7: =SUMIF('Tabla 2 - Ataques detec (Imple)'!$D$3:$D$112,$B7,'Tabla 2 - Ataques detec (Imple)'!AA$3:AA$112) -> 9 | AG7: =AF7 & " (" & AE7 & ")" -> 9 (11) | AH7: =SUMIF('Tabla 2 - Ataques detec (Imple)'!$D$3:$D$112,$B7,'Tabla 2 - Ataques detec (Imple)'!$AB$3:$AB$112) -> 9 | AI7: =AVERAGEIF('Tabla 2 - Ataques detec (Imple)'!$D$3:$D$112,$B7,'Tabla 2 - Ataques detec (Imple)'!$AD$3:$AD$112) -> 1 | AJ7: =SUMIF('Tabla 2 - Ataques detec (Imple)'!$D$3:$D$112,$B7,'Tabla 2 - Ataques detec (Imple)'!$AC$3:$AC$112) -> 8 | AK7: =SUMIF('Tabla 2 - Ataques detec (Imple)'!$D$3:$D$112,$B7,'Tabla 2 - Ataques detec (Imple)'!AE$3:AE$112) -> 13 | AL7: =SUMIF('Tabla 2 - Ataques detec (Imple)'!$D$3:$D$112,$B7,'Tabla 2 - Ataques detec (Imple)'!AF$3:AF$112) -> 11 | AM7: =AL7 & " (" & AK7 & ")" -> 11 (13) | AN7: =SUMIF('Tabla 2 - Ataques detec (Imple)'!$D$3:$D$112,$B7,'Tabla 2 - Ataques detec (Imple)'!$AG$3:$AG$112) -> 11 | AO7: =AVERAGEIF('Tabla 2 - Ataques detec (Imple)'!$D$3:$D$112,$B7,'Tabla 2 - Ataques detec (Imple)'!$AI$3:$AI$112) -> 1 | AP7: =SUMIF('Tabla 2 - Ataques detec (Imple)'!$D$3:$D$112,$B7,'Tabla 2 - Ataques detec (Imple)'!$AH$3:$AH$112) -> 9 | AQ7: =SUMIF('Tabla 2 - Ataques detec (Imple)'!$D$3:$D$112,$B7,'Tabla 2 - Ataques detec (Imple)'!AJ$3:AJ$112) -> 0 | AR7: =SUMIF('Tabla 2 - Ataques detec (Imple)'!$D$3:$D$112,$B7,'Tabla 2 - Ataques detec (Imple)'!AK$3:AK$112) -> 0 | AS7: =AR7 & " (" & AQ7 & ")" -> 0 (0) | AT7: =SUMIF('Tabla 2 - Ataques detec (Imple)'!$D$3:$D$112,$B7,'Tabla 2 - Ataques detec (Imple)'!$AL$3:$AL$112) -> 0 | AU7: =AVERAGEIF('Tabla 2 - Ataques detec (Imple)'!$D$3:$D$112,$B7,'Tabla 2 - Ataques detec (Imple)'!$AN$3:$AN$112) -> 0 | AV7: =SUMIF('Tabla 2 - Ataques detec (Imple)'!$D$3:$D$112,$B7,'Tabla 2 - Ataques detec (Imple)'!$AM$3:$AM$112) -> 0 | AW7: =SUMIF('Tabla 2 - Ataques detec (Imple)'!$D$3:$D$112,$B7,'Tabla 2 - Ataques detec (Imple)'!AO$3:AO$112) -> 2 | AX7: =SUMIF('Tabla 2 - Ataques detec (Imple)'!$D$3:$D$112,$B7,'Tabla 2 - Ataques detec (Imple)'!AP$3:AP$112) -> 2 | AY7: =AX7 & " (" & AW7 & ")" -> 2 (2) | AZ7: =SUMIF('Tabla 2 - Ataques detec (Imple)'!$D$3:$D$112,$B7,'Tabla 2 - Ataques detec (Imple)'!$AQ$3:$AQ$112) -> 2 | BA7: =AVERAGEIF('Tabla 2 - Ataques detec (Imple)'!$D$3:$D$112,$B7,'Tabla 2 - Ataques detec (Imple)'!$AS$3:$AS$112) -> 1 | BB7: =SUMIF('Tabla 2 - Ataques detec (Imple)'!$D$3:$D$112,$B7,'Tabla 2 - Ataques detec (Imple)'!$AR$3:$AR$112) -> 2 | BC7: =SUMIF('Tabla 2 - Ataques detec (Imple)'!$D$3:$D$112,$B7,'Tabla 2 - Ataques detec (Imple)'!AT$3:AT$112) -> 8 | BD7: =SUMIF('Tabla 2 - Ataques detec (Imple)'!$D$3:$D$112,$B7,'Tabla 2 - Ataques detec (Imple)'!AU$3:AU$112) -> 8 | BE7: =BD7 & " (" & BC7 & ")" -> 8 (8) | BF7: =SUMIF('Tabla 2 - Ataques detec (Imple)'!$D$3:$D$112,$B7,'Tabla 2 - Ataques detec (Imple)'!$AV$3:$AV$112) -> 8 | BG7: =AVERAGEIF('Tabla 2 - Ataques detec (Imple)'!$D$3:$D$112,$B7,'Tabla 2 - Ataques detec (Imple)'!$AX$3:$AX$112) -> 1 | BH7: =SUMIF('Tabla 2 - Ataques detec (Imple)'!$D$3:$D$112,$B7,'Tabla 2 - Ataques detec (Imple)'!$AW$3:$AW$112) -> 8 | BI7: =SUMIF('Tabla 2 - Ataques detec (Imple)'!$D$3:$D$112,$B7,'Tabla 2 - Ataques detec (Imple)'!AY$3:AY$112) -> 6 | BJ7: =SUMIF('Tabla 2 - Ataques detec (Imple)'!$D$3:$D$112,$B7,'Tabla 2 - Ataques detec (Imple)'!AZ$3:AZ$112) -> 6 | BK7: =BJ7 & " (" & BI7 & ")" -> 6 (6) | BL7: =SUMIF('Tabla 2 - Ataques detec (Imple)'!$D$3:$D$112,$B7,'Tabla 2 - Ataques detec (Imple)'!BA$3:BA$112) -> 1 | BM7: =AVERAGEIF('Tabla 2 - Ataques detec (Imple)'!$D$3:$D$112,$B7,'Tabla 2 - Ataques detec (Imple)'!$BC$3:$BC$112) -> 1 | BN7: =SUMIF('Tabla 2 - Ataques detec (Imple)'!$D$3:$D$112,$B7,'Tabla 2 - Ataques detec (Imple)'!$BB$3:$BB$112) -> 6 | BO7: =SUMIF('Tabla 2 - Ataques detec (Imple)'!$D$3:$D$112,$B7,'Tabla 2 - Ataques detec (Imple)'!BD$3:BD$112) -> 6 | BP7: =SUMIF('Tabla 2 - Ataques detec (Imple)'!$D$3:$D$112,$B7,'Tabla 2 - Ataques detec (Imple)'!BE$3:BE$112) -> 6 | BQ7: =BP7 & " (" & BO7 & ")" -> 6 (6) | BR7: =SUMIF('Tabla 2 - Ataques detec (Imple)'!$D$3:$D$112,$B7,'Tabla 2 - Ataques detec (Imple)'!BF$3:BF$112) -> 1 | BS7: =SUMIF('Tabla 2 - Ataques detec (Imple)'!$D$3:$D$112,$B7,'Tabla 2 - Ataques detec (Imple)'!BG$3:BG$112) -> 0 | BT7: =AVERAGEIF('Tabla 2 - Ataques detec (Imple)'!$D$3:$D$112,$B7,'Tabla 2 - Ataques detec (Imple)'!$BI$3:$BI$112) -> 1 | BU7: =SUMIF('Tabla 2 - Ataques detec (Imple)'!$D$3:$D$112,$B7,'Tabla 2 - Ataques detec (Imple)'!$BH$3:$BH$112) -> 6 | BV7: 0 | BW7: 0 | BX7: =BW7 & " (" & BV7 & ")" -> 0 (0) | BY7: 0 | BZ7: 0 | CA7: 0 | CB7: 0 | CC7: 0 | CD7: =CC7 & " (" & CB7 & ")" -> 0 (0) | CE7: 0 | CF7: 0 | CG7: 0 | CH7: 0
